Workbook

Sheet Resumen
G2: GRUPO ASERCOM, S.A. DE C.V.
G3: División Telecomunicaciones
B8: Cotizado a: | G8: Fecha:
B9: ICL FOSFATOS Y ADITIVOS MEXICO, S.A. DE C.V. | G9: 10 de Septiembre del 2015
B10: Atención: | G10: Tiempo de Entrega
B11: Ing. Ernesto Ramos | G11: Material y Equipo: | I11: 4 a 6 Sem | J11: Ejecución: | K11: 10 dias
B12: Validez de la oferta: | D12: 15 días | G12: Numero de Cotización:
B13: Condiciones de pago:
B16: En respuesta a su amable solicitud ponemos a su consideración la siguiente cotización para el Proyecto de:
B17: Seguridad en la Planta
H20: Material | J20: Mano de Obra
C24: 1 | D24: =Acceso!B17 -> Control de Acceso Area Almacen | H24: =Acceso!G45 -> 1391.97 | I24: USD | J24: =Acceso!I45 -> 453.828 | K24: USD
C26: 2 | D26: =AP!B17 -> Canalizacion para Acces Point en Area de Terminados | H26: =AP!G31 -> 288.48 | I26: USD | J26: =AP!I31 -> 284.472 | K26: USD
C28: 3 | D28: =CCTV!B17 -> Camara Comedor | H28: =CCTV!G30 -> 1091.9 | I28: USD | J28: =CCTV!I30 -> 208.75 | K28: USD
F29: Sub-Totales sin IVA | H29: =SUM(H24:H28) -> 2772.35 | I29: USD | J29: =SUM(J24:J28) -> 947.05 | K29: USD
F31: Sub-Total sin IVA | H31: =H29+J29 -> 3719.4
B35: NOTAS: | D35: CONMUTADOR TELEFONICO 1232
D36: CAPACIDAD ACTUAL: 4 LINEAS 4 EXTENSIONES
D37: CAPACIDAD PROPUESTA: 8 LINEAS 16 EXTENSIONES, 2 EXTENSIONES PARA CORREO DE VOZ, 4 EXTENSIONES ACTUALES Y 10 EXTENSIONES A FUTURO
B40: AGENTE GRUPO ASERCOM | G40: AUTORIZACION CLIENTE
B42: NOMBRE | C42: DENNISE MARES LEAL | G42: NOMBRE
B44: FIRMA | G44: FIRMA
B49: Grupo Asercom, S.A. de C.V. | E49: www.grupoasercom.com
B50: Corporativo Monterrey | E50: Sucursal Guadalajara | I50: Sucursal México, D.F.
B51: Joaquín García No. 217 Col. Burócratas | E51: Av. Circunvalación Agustín Yáñez No. 2360 Int 4-A | I51: Río Lerma No. 26 Col. Cuauhtémoc
B52: Del Estado Monterrey, N.L. C.P. 64380 | E52: Col. Arcos Sur Guadalajara, Jal. C.P. 44150 | I52: Del. Cuauhtémoc México, D.F. C.P. 06500
B53: Conmutador (81) 1442-4000 | E53: Tels (33) 3630-5030 y 3630-5033 | I53: Tels (55) 5703-0028 y 5703-0141

Sheet Acceso
G2: GRUPO ASERCOM, S.A. DE C.V.
G3: División Telecomunicaciones
B8: Cotizado a: | G8: Fecha:
B9: ICL FOSFATOS Y ADITIVOS MEXICO, S.A. DE C.V. | G9: 10 de Septiembre del 2015
B10: Atención: | G10: Tiempo de Entrega
B11: Ing. Ernesto Ramos | G11: Material y Equipo: | I11: 4 a 6 Sem | J11: Ejecución: | K11: 4 dias
B12: Validez de la oferta: | D12: 15 días | G12: Numero de Cotización:
B13: Condiciones de pago:
B16: En respuesta a su amable solicitud ponemos a su consideración la siguiente cotización para el Proyecto de:
B17: Control de Acceso Area Almacen
B19: Cant | C19: Descripción | F19: No. Parte | G19: Material | I19: Mano de Obra | K19: Total
G20: Precio Unitario | H20: Importe | I20: Precio Unitario | J20: Importe
C21: Equipo Activo
B22: 1 | C22: Control de acceso para 2 Puertas 4 Lectoras | F22: C3200 | G22: 245 | H22: =G22*B22 -> 245 | I22: 35 | J22: =I22*B22 -> 35 | K22: =SUM(J22+H22) -> 280
B23: 2 | C23: Lector de Proximidad | F23: K-PROX2 | G23: 166 | H23: =G23*B23 -> 332 | I23: 15 | J23: =I23*B23 -> 30 | K23: =SUM(J23+H23) -> 362
B24: 2 | C24: Botón de Salida Sin Contacto | F24: SYSB11 | G24: 18 | H24: =G24*B24 -> 36 | I24: 5 | J24: =I24*B24 -> 10 | K24: =SUM(J24+H24) -> 46
B25: 100 | C25: Cable 6 Conductores Calibre 22, Para Aplicaciones Básicas | F25: EP2206V2 | G25: 0.65 | H25: =G25*B25 -> 65 | I25: 0.32 | J25: =I25*B25 -> 32 | K25: =SUM(J25+H25) -> 97
B26: 40 | C26: Cable 2 Conductores Calibre 22, Para Aplicaciones Básicas | F26: 1118580 | G26: 0.69 | H26: =G26*B26 -> 27.6 | I26: 0.32 | J26: =I26*B26 -> 12.8 | K26: =SUM(J26+H26) -> 40.4
B27: 2 | C27: Chapa magnética de 600 lbs con sensor de bloqueo de placa y puerta, LED y temporizador | F27: PROMAG600S | G27: 79 | H27: =G27*B27 -> 158 | I27: 20 | J27: =I27*B27 -> 40 | K27: =SUM(J27+H27) -> 198
B28: 2 | C28: Bracket de Alumnio en “Z” | F28: PROBZ600 | G28: 13 | H28: =G28*B28 -> 26 | I28: 8 | J28: =I28*B28 -> 16 | K28: =SUM(J28+H28) -> 42
B29: 2 | C29: Estación manual de emergencia en Policarbonato de Alta Resistencia | F29: 904PB | G29: 75 | H29: =G29*B29 -> 150 | I29: 10 | J29: =I29*B29 -> 20 | K29: =SUM(J29+H29) -> 170
B30: 10 | C30: Metro de Cable UTP Cat 6, color Azul | F30: PUC6004BU | G30: 0.89 | H30: =G30*B30 -> 8.9 | I30: 0.32 | J30: =I30*B30 -> 3.2 | K30: =SUM(J30+H30) -> 12.1
B31: 5 | C31: Conector RJ45 para Cable FTP/STP Categoría 5E - Blindado | F31: TC5S | G31: 0.9 | H31: =G31*B31 -> 4.5 | I31: 0.36 | J31: =I31*B31 -> 1.8 | K31: =SUM(J31+H31) -> 6.3
B32: 1 | C32: Fuente de 12 Vcd/1A para Control de Acceso con Batería Incluida | F32: PRO12V1AK | G32: 72 | H32: =G32*B32 -> 72 | I32: 15 | J32: =I32*B32 -> 15 | K32: =SUM(J32+H32) -> 87
B33: 1 | C33: Batería con Tecnología AGM / VRLA, 4.5 Ah. | F33: PL4.512 | G33: 14 | H33: =G33*B33 -> 14 | I33: 5 | J33: =I33*B33 -> 5 | K33: =SUM(J33+H33) -> 19
C34: Canalizacion
B35: 13 | C35: Tubo Conduit Pared Gruesa 3/4" | F35: N/A | G35: 4.89 | H35: =G35*B35 -> 63.57 | I35: 1.956 | J35: =I35*B35 -> 25.428 | K35: =SUM(J35+H35) -> 88.998
B36: 5 | C36: Cople Conduit pared Gruesa 3/4" | F36: N/A | G36: 0.54 | H36: =G36*B36 -> 2.7 | I36: 0.216 | J36: =I36*B36 -> 1.08 | K36: =SUM(J36+H36) -> 3.78
B37: 6 | C37: Condulet LB de 3/4" | F37: N/A | G37: 6.2 | H37: =G37*B37 -> 37.2 | I37: 2.48 | J37: =I37*B37 -> 14.88 | K37: =SUM(J37+H37) -> 52.08
B38: 2 | C38: Condulet LR de 3/4" | F38: N/A | G38: 6.2 | H38: =G38*B38 -> 12.4 | I38: 2.48 | J38: =I38*B38 -> 4.96 | K38: =SUM(J38+H38) -> 17.36
B39: 1 | C39: Condulet T de 3/4" | F39: N/A | G39: 6.5 | H39: =G39*B39 -> 6.5 | I39: 2.48 | J39: =I39*B39 -> 2.48 | K39: =SUM(J39+H39) -> 8.98
B40: 20 | C40: Soporteria para tuberia 3/4" | F40: N/A | G40: 2.65 | H40: =G40*B40 -> 53 | I40: 1.06 | J40: =I40*B40 -> 21.2 | K40: =SUM(J40+H40) -> 74.2
B41: 2 | C41: Caja FS de 2"x4", con salida de 3/4" | F41: N/A | G41: 19.4 | H41: =G41*B41 -> 38.8 | I41: 9.5 | J41: =I41*B41 -> 19 | K41: =SUM(J41+H41) -> 57.8
B42: 2 | C42: Caja FS de 2"x4", con salida de 3/4" de paso | F42: N/A | G42: 19.4 | H42: =G42*B42 -> 38.8 | I42: 9.5 | J42: =I42*B42 -> 19 | K42: =SUM(J42+H42) -> 57.8
B43: 1 | C43: Lote de Miscelaneos | F43: Serv-Inst | G43: 0 | H43: =G43*B43 -> 0 | I43: 25 | J43: =I43*B43 -> 25 | K43: =SUM(J43+H43) -> 25
B44: 1 | C44: Servicio de Configuracion de equipo, ajuste y Calibracion de puertas | F44: Serv-Inst | G44: 0 | H44: =G44*B44 -> 0 | I44: 100 | J44: =I44*B44 -> 100 | K44: =SUM(J44+H44) -> 100
E45: Sub Total Material / Mano de Obra | G45: =SUM(H22:H44) -> 1391.97 | I45: =SUM(J22:J44) -> 453.828
E46: Sub Total sin IVA | G46: =SUM(K19:K45) -> 1845.798
B49: NOTAS:
B53: X | C53: USD | D53: LOS PRECIOS ESTAN COTIZADOS EN USD PAGADEROS CON LA MISMA MONEDA Y NO INCLUYEN IVA
...

Sheet AP
G2: GRUPO ASERCOM, S.A. DE C.V.
G3: División Telecomunicaciones
B8: Cotizado a: | G8: Fecha:
B9: ICL FOSFATOS Y ADITIVOS MEXICO, S.A. DE C.V. | G9: 10 de Septiembre del 2015
B10: Atención: | G10: Tiempo de Entrega
B11: Ing. Ernesto Ramos | G11: Material y Equipo: | I11: 2 dias | J11: Ejecución: | K11: 2 dias
B12: Validez de la oferta: | D12: 15 días | G12: Numero de Cotización:
B13: Condiciones de pago:
B16: En respuesta a su amable solicitud ponemos a su consideración la siguiente cotización para el Proyecto de:
B17: Canalizacion para Acces Point en Area de Terminados
B19: Cant | C19: Descripción | F19: No. Parte | G19: Material | I19: Mano de Obra | K19: Total
G20: Precio Unitario | H20: Importe | I20: Precio Unitario | J20: Importe
C21: Canalizacion
B22: 6 | C22: Tubo Conduit Pared Gruesa 3/4" | F22: N/A | G22: 4.89 | H22: =G22*B22 -> 29.34 | I22: 1.956 | J22: =I22*B22 -> 11.736 | K22: =SUM(J22+H22) -> 41.076
B23: 6 | C23: Cople Conduit pared Gruesa 3/4" | F23: N/A | G23: 0.54 | H23: =G23*B23 -> 3.24 | I23: 0.216 | J23: =I23*B23 -> 1.296 | K23: =SUM(J23+H23) -> 4.536
B24: 3 | C24: Condulet LB de 3/4" | F24: N/A | G24: 6.2 | H24: =G24*B24 -> 18.6 | I24: 2.48 | J24: =I24*B24 -> 7.44 | K24: =SUM(J24+H24) -> 26.04
B25: 20 | C25: Soporte para Tubo Conduit a base de Abrazadera Tipo Clip, Varilla Roscada, Mordaza, Tuerca, Tornillo | F25: N/A | G25: 6.5 | H25: =G25*B25 -> 130 | I25: 5 | J25: =I25*B25 -> 100 | K25: =SUM(J25+H25) -> 230
B26: 2 | C26: Unicanal Perforada 2x4" | F26: N/A | G26: 4.5 | H26: =G26*B26 -> 9 | I26: 9.5 | J26: =I26*B26 -> 19 | K26: =SUM(J26+H26) -> 28
B27: 2 | C27: Caja FS de 2"x4", con salida de 3/4" de paso | F27: N/A | G27: 19.4 | H27: =G27*B27 -> 38.8 | I27: 9.5 | J27: =I27*B27 -> 19 | K27: =SUM(J27+H27) -> 57.8
B28: 50 | C28: Metro de Cable UTP Cat 6, color Azul | F28: PUC6004BU | G28: 0.89 | H28: =G28*B28 -> 44.5 | I28: 0.32 | J28: =I28*B28 -> 16 | K28: =SUM(J28+H28) -> 60.5
B29: 1 | C29: Lote de Miscelaneos | F29: Serv-Inst | G29: 15 | H29: =G29*B29 -> 15 | I29: 25 | J29: =I29*B29 -> 25 | K29: =SUM(J29+H29) -> 40
B30: 1 | C30: Servicio de instalacion de acceso point y requerimientos de canalizacion | F30: Serv-Inst | G30: 0 | H30: =G30*B30 -> 0 | I30: 100 | J30: 85 | K30: =SUM(J30+H30) -> 85
E31: Sub Total Material / Mano de Obra | G31: =SUM(H21:H30) -> 288.48 | I31: =SUM(J21:J30) -> 284.472
E32: Sub Total sin IVA | G32: =SUM(K19:K31) -> 572.952
B35: NOTAS:
B39: X | C39: USD | D39: LOS PRECIOS ESTAN COTIZADOS EN USD PAGADEROS CON LA MISMA MONEDA Y NO INCLUYEN IVA
C40: MN | D40: LOS PRECIOS ESTAN COTIZADOS EN MONEDA NACIONA Y NO INCLUYEN IVA
B44: AGENTE GRUPO ASERCOM | G44: AUTORIZACION CLIENTE
B46: NOMBRE | C46: DENNISE MARES LEAL | G46: NOMBRE
B48: FIRMA | G48: FIRMA
B53: Grupo Asercom, S.A. de C.V. | E53: www.grupoasercom.com
B54: Corporativo Monterrey | E54: Sucursal Guadalajara | I54: Sucursal México, D.F.
B55: Joaquín García No. 217 Col. Burócratas | E55: Av. Circunvalación Agustín Yáñez No. 2360 Int 4-A | I55: Río Lerma No. 26 Col. Cuauhtémoc
B56: Del Estado Monterrey, N.L. C.P. 64380 | E56: Col. Arcos Sur Guadalajara, Jal. C.P. 44150 | I56: Del. Cuauhtémoc México, D.F. C.P. 06500
B57: Conmutador (81) 1442-4000 | E57: Tels (33) 3630-5030 y 3630-5033 | I57: Tels (55) 5703-0028 y 5703-0141

Sheet CCTV
G2: GRUPO ASERCOM, S.A. DE C.V.
G3: División Telecomunicaciones
B8: Cotizado a: | G8: Fecha:
B9: ICL FOSFATOS Y ADITIVOS MEXICO, S.A. DE C.V. | G9: 10 de Septiembre del 2015
B10: Atención: | G10: Tiempo de Entrega
B11: Ing. Ernesto Ramos | G11: Material y Equipo: | I11: 4 a 6 Sem | J11: Ejecución: | K11: 4 dias
B12: Validez de la oferta: | D12: 15 días | G12: Numero de Cotización:
B13: Condiciones de pago:
B16: En respuesta a su amable solicitud ponemos a su consideración la siguiente cotización para el Proyecto de:
B17: Camara Comedor
B19: Cant | C19: Descripción | F19: No. Parte | G19: Material | I19: Mano de Obra | K19: Total
G20: Precio Unitario | H20: Importe | I20: Precio Unitario | J20: Importe
C21: Equipo Activo
B22: 1 | C22: IP Sarix E SFMT POE Mdome 1MP 30IPS Surevision WC | F22: IME119-1S | G22: 854 | H22: =G22*B22 -> 854 | I22: 48 | J22: =I22*B22 -> 48 | K22: =SUM(J22+H22) -> 902
B23: 1 | C23: Licencia Para Camara IP De Pelco Para DS | F23: DS-SW-CAM | G23: 148 | H23: =G23*B23 -> 148 | I23: 0 | J23: =I23*B23 -> 0 | K23: =SUM(J23+H23) -> 148
B24: 10 | C24: Metro de Cable UTP Cat 6, color Azul | F24: PUC6004BU | G24: 0.89 | H24: =G24*B24 -> 8.9 | I24: 0.45 | J24: =I24*B24 -> 4.5 | K24: =SUM(J24+H24) -> 13.4
B25: 5 | C25: Conector RJ45 para Cable FTP/STP Categoría 5E - Blindado | F25: TC5S | G25: 0.9 | H25: =G25*B25 -> 4.5 | I25: 0.45 | J25: =I25*B25 -> 2.25 | K25: =SUM(J25+H25) -> 6.75
B26: 5 | C26: Tramo de Canaleta LD5, Color blanco | F26: LD5WH6-A | G26: 7.3 | H26: =G26*B26 -> 36.5 | I26: 2.8 | J26: =I26*B26 -> 14 | K26: =SUM(J26+H26) -> 50.5
B27: 10 | C27: Accesorio para Canaleta LD5, Color blanco | F27: N/A | G27: 2.5 | H27: =G27*B27 -> 25 | I27: 1.5 | J27: =I27*B27 -> 15 | K27: =SUM(J27+H27) -> 40
B28: 1 | C28: Lote de Miscelaneos | F28: Serv-Inst | G28: 15 | H28: =G28*B28 -> 15 | I28: 25 | J28: =I28*B28 -> 25 | K28: =SUM(J28+H28) -> 40
B29: 1 | C29: Servicio de Configuracion de equipo,Enfoque y puesta a punto | F29: Serv-Inst | G29: 0 | H29: =G29*B29 -> 0 | I29: 100 | J29: =I29*B29 -> 100 | K29: =SUM(J29+H29) -> 100
E30: Sub Total Material / Mano de Obra | G30: =SUM(H22:H29) -> 1091.9 | I30: =SUM(J22:J29) -> 208.75
E31: Sub Total sin IVA | G31: =SUM(K19:K30) -> 1300.65
B34: NOTAS:
B38: X | C38: USD | D38: LOS PRECIOS ESTAN COTIZADOS EN USD PAGADEROS CON LA MISMA MONEDA Y NO INCLUYEN IVA
C39: MN | D39: LOS PRECIOS ESTAN COTIZADOS EN MONEDA NACIONA Y NO INCLUYEN IVA
B43: AGENTE GRUPO ASERCOM | G43: AUTORIZACION CLIENTE
B45: NOMBRE | C45: DENNISE MARES LEAL | G45: NOMBRE
B47: FIRMA | G47: FIRMA
B52: Grupo Asercom, S.A. de C.V. | E52: www.grupoasercom.com
B53: Corporativo Monterrey | E53: Sucursal Guadalajara | I53: Sucursal México, D.F.
B54: Joaquín García No. 217 Col. Burócratas | E54: Av. Circunvalación Agustín Yáñez No. 2360 Int 4-A | I54: Río Lerma No. 26 Col. Cuauhtémoc
B55: Del Estado Monterrey, N.L. C.P. 64380 | E55: Col. Arcos Sur Guadalajara, Jal. C.P. 44150 | I55: Del. Cuauhtémoc México, D.F. C.P. 06500
B56: Conmutador (81) 1442-4000 | E56: Tels (33) 3630-5030 y 3630-5033 | I56: Tels (55) 5703-0028 y 5703-0141
